<?xml version="1.0" ?>
<!-- =================================================================================== -->
<!-- |    This document was autogenerated by xacro from tflow.xacro                    | -->
<!-- |    EDITING THIS FILE BY HAND IS NOT RECOMMENDED                                 | -->
<!-- =================================================================================== -->
<robot name="tflow" xmlns:xacro="http://ros.org/wiki/xacro">
  <link name="base_link">
    <visual>
      <geometry>
        <box size="0.18 0.12 0.08"/>
      </geometry>
      <origin rpy="0 0 0" xyz="0 0 0"/>
      <material name="silver">
        <color rgba="0.5 0.5 0.5 1"/>
      </material>
    </visual>
    <collision>
      <geometry>
        <box size="0.18 0.12 0.08"/>
      </geometry>
      <origin rpy="0 0 0" xyz="0 0 0"/>
      <material name="silver">
        <color rgba="0.5 0.5 0.5 1"/>
      </material>
    </collision>
    <inertial>
      <mass value="0.01"/>
      <inertia ixx="0.0" ixy="0.0" ixz="0.0" iyy="0.0" iyz="0.0" izz="0.0"/>
    </inertial>
  </link>
  <!-- PERUT -->
  <link name="servo_perut_roll_1">
    <visual>
      <geometry>
        <box size="0.0402 0.046 0.0651"/>
      </geometry>
      <origin rpy="0.0 0.0 1.57" xyz="0 0 0"/>
      <material name="silver">
        <color rgba="0.3 0.3 0.3 1"/>
      </material>
    </visual>
    <collision>
      <geometry>
        <box size="0.0402 0.046 0.0651"/>
      </geometry>
      <origin rpy="0.0 0.0 1.57" xyz="0 0 0"/>
    </collision>
    <inertial>
      <mass value="0.153"/>
      <inertia ixx="0.0" ixy="0.0" ixz="0.0" iyy="0.0" iyz="0.0" izz="0.0"/>
    </inertial>
  </link>
  <link name="servo_perut_roll_2">
    <visual>
      <geometry>
        <box size="0.0402 0.046 0.0651"/>
      </geometry>
      <origin rpy="0.0 0.0 -1.57" xyz="0 0 0"/>
      <material name="silver">
        <color rgba="0.3 0.3 0.3 1"/>
      </material>
    </visual>
    <collision>
      <geometry>
        <box size="0.0402 0.046 0.0651"/>
      </geometry>
      <origin rpy="0.0 0.0 -1.57" xyz="0 0 0"/>
    </collision>
    <inertial>
      <mass value="0.153"/>
      <inertia ixx="0.0" ixy="0.0" ixz="0.0" iyy="0.0" iyz="0.0" izz="0.0"/>
    </inertial>
  </link>
  <link name="servo_perut_pitch">
    <visual>
      <geometry>
        <box size="0.0402 0.046 0.0651"/>
      </geometry>
      <origin rpy="0.0 0.0 0" xyz="0 0 0"/>
      <material name="silver">
        <color rgba="0.3 0.3 0.3 1"/>
      </material>
    </visual>
    <collision>
      <geometry>
        <box size="0.0402 0.046 0.0651"/>
      </geometry>
      <origin rpy="0.0 0.0 0" xyz="0 0 0"/>
    </collision>
    <inertial>
      <mass value="0.153"/>
      <inertia ixx="0.0" ixy="0.0" ixz="0.0" iyy="0.0" iyz="0.0" izz="0.0"/>
    </inertial>
  </link>
  <link name="link_perut_yaw">
    <visual>
      <geometry>
        <cylinder length="0.04" radius="0.02"/>
      </geometry>
      <origin rpy="0.0 0.0 0" xyz="0 0 0.03"/>
      <material name="white">
        <color rgba="0.8 0.8 0.8 1"/>
      </material>
    </visual>
    <collision>
      <geometry>
        <cylinder length="0.04" radius="0.02"/>
      </geometry>
      <origin rpy="0.0 0.0 0" xyz="0 0 0.03"/>
    </collision>
    <inertial>
      <mass value="0.0008"/>
      <inertia ixx="0.0" ixy="0.0" ixz="0.0" iyy="0.0" iyz="0.0" izz="0.0"/>
    </inertial>
  </link>
  <link name="servo_perut_yaw">
    <visual>
      <geometry>
        <box size="0.0402 0.046 0.0651"/>
      </geometry>
      <origin rpy="-1.57 0.0 0" xyz="0 0 0.02"/>
      <material name="silver">
        <color rgba="0.3 0.3 0.3 1"/>
      </material>
    </visual>
    <collision>
      <geometry>
        <box size="0.0402 0.046 0.0651"/>
      </geometry>
      <origin rpy="-1.57 0.0 0" xyz="0 0 0.02"/>
    </collision>
    <inertial>
      <mass value="0.153"/>
      <inertia ixx="0.0" ixy="0.0" ixz="0.0" iyy="0.0" iyz="0.0" izz="0.0"/>
    </inertial>
  </link>
  <!-- PERUT_END -->
  <!-- Kepala -->
  <link name="servo_kepala_yaw">
    <visual>
      <geometry>
        <box size="0.0356 0.0355 0.0506"/>
      </geometry>
      <origin rpy="1.57 0.0 0" xyz="0 0 0.0"/>
      <material name="silver">
        <color rgba="0.5 0.5 0.5 1"/>
      </material>
    </visual>
    <collision>
      <geometry>
        <box size="0.0356 0.0355 0.0506"/>
      </geometry>
      <origin rpy="1.57 0.0 0" xyz="0 0 0.0"/>
    </collision>
    <inertial>
      <mass value="0.072"/>
      <inertia ixx="0.0" ixy="0.0" ixz="0.0" iyy="0.0" iyz="0.0" izz="0.0"/>
    </inertial>
  </link>
  <link name="link_leher">
    <visual>
      <geometry>
        <cylinder length="0.031" radius="0.015"/>
      </geometry>
      <origin rpy="0.0 0.0 0" xyz="0 0 0.0"/>
      <material name="white">
        <color rgba="0.8 0.8 0.8 1"/>
      </material>
    </visual>
    <collision>
      <geometry>
        <cylinder length="0.031" radius="0.015"/>
      </geometry>
      <origin rpy="0.0 0.0 0" xyz="0 0 0.0"/>
    </collision>
    <inertial>
      <mass value="0.000465"/>
      <inertia ixx="0.0" ixy="0.0" ixz="0.0" iyy="0.0" iyz="0.0" izz="0.0"/>
    </inertial>
  </link>
  <link name="servo_kepala_pitch">
    <visual>
      <geometry>
        <box size="0.0356 0.0355 0.0506"/>
      </geometry>
      <origin rpy="0.0 0.0 0" xyz="0 -0.04 0.0"/>
      <material name="silver">
        <color rgba="0.5 0.5 0.5 1"/>
      </material>
    </visual>
    <collision>
      <geometry>
        <box size="0.0356 0.0355 0.0506"/>
      </geometry>
      <origin rpy="0.0 0.0 0" xyz="0 -0.04 0.0"/>
    </collision>
    <inertial>
      <mass value="0.072"/>
      <inertia ixx="0.0" ixy="0.0" ixz="0.0" iyy="0.0" iyz="0.0" izz="0.0"/>
    </inertial>
  </link>
  <link name="servo_kepala_roll">
    <visual>
      <geometry>
        <box size="0.0356 0.0355 0.0506"/>
      </geometry>
      <origin rpy="0.0 0.0 0" xyz="0 0.0 0.0"/>
      <material name="silver">
        <color rgba="0.5 0.5 0.5 1"/>
      </material>
    </visual>
    <collision>
      <geometry>
        <box size="0.0356 0.0355 0.0506"/>
      </geometry>
      <origin rpy="0.0 0.0 0" xyz="0 0.0 0.0"/>
    </collision>
    <inertial>
      <mass value="0.072"/>
      <inertia ixx="0.0" ixy="0.0" ixz="0.0" iyy="0.0" iyz="0.0" izz="0.0"/>
    </inertial>
  </link>
  <link name="kepala">
    <visual>
      <geometry>
        <box size="0.125 0.085 0.042"/>
      </geometry>
      <origin rpy="0.0 0.0 0" xyz="0 0 0.07"/>
      <material name="white">
        <color rgba="0.8 0.8 0.8 1"/>
      </material>
    </visual>
    <collision>
      <geometry>
        <box size="0.125 0.085 0.042"/>
      </geometry>
      <origin rpy="0.0 0.0 0" xyz="0 0 0.07"/>
    </collision>
    <inertial>
      <mass value="0.00044625"/>
      <inertia ixx="0.0" ixy="0.0" ixz="0.0" iyy="0.0" iyz="0.0" izz="0.0"/>
    </inertial>
  </link>
  <!-- Kepala_END -->
  <!-- Tangan_Kanan -->
  <link name="servo_bahu_kanan_roll">
    <visual>
      <geometry>
        <box size="0.0402 0.046 0.0651"/>
      </geometry>
      <origin rpy="-1.57 0 0" xyz="0 0 0"/>
      <material name="silver">
        <color rgba="0.3 0.3 0.3 1"/>
      </material>
    </visual>
    <collision>
      <geometry>
        <box size="0.0402 0.046 0.0651"/>
      </geometry>
      <origin rpy="-1.57 0 0" xyz="0 0 0"/>
    </collision>
    <inertial>
      <mass value="0.153"/>
      <inertia ixx="0.0" ixy="0.0" ixz="0.0" iyy="0.0" iyz="0.0" izz="0.0"/>
    </inertial>
  </link>
  <link name="servo_bahu_kanan_pitch">
    <visual>
      <geometry>
        <box size="0.0402 0.046 0.0651"/>
      </geometry>
      <origin rpy="0 1.57 0" xyz="0 0 0"/>
      <material name="silver">
        <color rgba="0.3 0.3 0.3 1"/>
      </material>
    </visual>
    <collision>
      <geometry>
        <box size="0.0402 0.046 0.0651"/>
      </geometry>
      <origin rpy="0 1.57 0" xyz="0 0 0"/>
    </collision>
    <inertial>
      <mass value="0.153"/>
      <inertia ixx="0.0" ixy="0.0" ixz="0.0" iyy="0.0" iyz="0.0" izz="0.0"/>
    </inertial>
  </link>
  <link name="link_siku_kanan">
    <visual>
      <geometry>
        <cylinder length="0.195" radius="0.01"/>
      </geometry>
      <origin rpy="0.0 1.57 0" xyz="0.0975 0 0.0"/>
      <material name="white">
        <color rgba="0.8 0.8 0.8 1"/>
      </material>
    </visual>
    <collision>
      <geometry>
        <cylinder length="0.195" radius="0.01"/>
      </geometry>
      <origin rpy="0.0 1.57 0" xyz="0.0975 0 0.0"/>
    </collision>
    <inertial>
      <mass value="0.00195"/>
      <inertia ixx="0.0" ixy="0.0" ixz="0.0" iyy="0.0" iyz="0.0" izz="0.0"/>
    </inertial>
  </link>
  <link name="servo_siku_kanan_pitch">
    <visual>
      <geometry>
        <box size="0.0402 0.046 0.0651"/>
      </geometry>
      <origin rpy="0 1.57 1.57" xyz="0 0 0"/>
      <material name="silver">
        <color rgba="0.3 0.3 0.3 1"/>
      </material>
    </visual>
    <collision>
      <geometry>
        <box size="0.0402 0.046 0.0651"/>
      </geometry>
      <origin rpy="0 1.57 1.57" xyz="0 0 0"/>
    </collision>
    <inertial>
      <mass value="0.153"/>
      <inertia ixx="0.0" ixy="0.0" ixz="0.0" iyy="0.0" iyz="0.0" izz="0.0"/>
    </inertial>
  </link>
  <link name="link_lengan_kanan">
    <visual>
      <geometry>
        <cylinder length="0.15" radius="0.01"/>
      </geometry>
      <origin rpy="0.0 1.57 0" xyz="-0.08 0 0.0"/>
      <material name="white">
        <color rgba="0.8 0.8 0.8 1"/>
      </material>
    </visual>
    <collision>
      <geometry>
        <cylinder length="0.15" radius="0.01"/>
      </geometry>
      <origin rpy="0.0 1.57 0" xyz="-0.08 0 0.0"/>
    </collision>
    <inertial>
      <mass value="0.0015"/>
      <inertia ixx="0.0" ixy="0.0" ixz="0.0" iyy="0.0" iyz="0.0" izz="0.0"/>
    </inertial>
  </link>
  <link name="link_telapak_kanan">
    <visual>
      <geometry>
        <box size="0.015 0.07 0.04"/>
      </geometry>
      <origin rpy="0.0 0 0" xyz="0 0 0.0"/>
      <material name="black">
        <color rgba="0 0 0 1"/>
      </material>
    </visual>
    <collision>
      <geometry>
        <box size="0.015 0.07 0.04"/>
      </geometry>
      <origin rpy="0.0 0 0" xyz="0 0 0.0"/>
    </collision>
    <inertial>
      <mass value="4.2e-05"/>
      <inertia ixx="0.0" ixy="0.0" ixz="0.0" iyy="0.0" iyz="0.0" izz="0.0"/>
    </inertial>
  </link>
  <link name="telapak_tangan_kanan">
    <visual>
      <geometry>
        <cylinder length="0.01" radius="0.0625"/>
      </geometry>
      <origin rpy="0.0 0 0" xyz="0 0 0.0"/>
      <material name="black">
        <color rgba="0 0 0 1"/>
      </material>
    </visual>
    <collision>
      <geometry>
        <cylinder length="0.01" radius="0.0625"/>
      </geometry>
      <origin rpy="0.0 0 0" xyz="0 0 0.0"/>
    </collision>
    <inertial>
      <mass value="0.000625"/>
      <inertia ixx="0.0" ixy="0.0" ixz="0.0" iyy="0.0" iyz="0.0" izz="0.0"/>
    </inertial>
  </link>
  <!-- Tangan_Kanan_END -->
  <!-- Tangan_Kiri -->
  <link name="servo_bahu_kiri_roll">
    <visual>
      <geometry>
        <box size="0.0402 0.046 0.0651"/>
      </geometry>
      <origin rpy="1.57 0 0" xyz="0 0 0"/>
      <material name="silver">
        <color rgba="0.3 0.3 0.3 1"/>
      </material>
    </visual>
    <collision>
      <geometry>
        <box size="0.0402 0.046 0.0651"/>
      </geometry>
      <origin rpy="1.57 0 0" xyz="0 0 0"/>
    </collision>
    <inertial>
      <mass value="0.153"/>
      <inertia ixx="0.0" ixy="0.0" ixz="0.0" iyy="0.0" iyz="0.0" izz="0.0"/>
    </inertial>
  </link>
  <link name="servo_bahu_kiri_pitch">
    <visual>
      <geometry>
        <box size="0.0402 0.046 0.0651"/>
      </geometry>
      <origin rpy="0 -1.57 0" xyz="0 0 0"/>
      <material name="silver">
        <color rgba="0.3 0.3 0.3 1"/>
      </material>
    </visual>
    <collision>
      <geometry>
        <box size="0.0402 0.046 0.0651"/>
      </geometry>
      <origin rpy="0 -1.57 0" xyz="0 0 0"/>
    </collision>
    <inertial>
      <mass value="0.153"/>
      <inertia ixx="0.0" ixy="0.0" ixz="0.0" iyy="0.0" iyz="0.0" izz="0.0"/>
    </inertial>
  </link>
  <link name="link_siku_kiri">
    <visual>
      <geometry>
        <cylinder length="0.195" radius="0.01"/>
      </geometry>
      <origin rpy="0.0 -1.57 0" xyz="-0.0975 0 0.0"/>
      <material name="white">
        <color rgba="0.8 0.8 0.8 1"/>
      </material>
    </visual>
    <collision>
      <geometry>
        <cylinder length="0.195" radius="0.01"/>
      </geometry>
      <origin rpy="0.0 -1.57 0" xyz="-0.0975 0 0.0"/>
    </collision>
    <inertial>
      <mass value="0.00195"/>
      <inertia ixx="0.0" ixy="0.0" ixz="0.0" iyy="0.0" iyz="0.0" izz="0.0"/>
    </inertial>
  </link>
  <link name="servo_siku_kiri_pitch">
    <visual>
      <geometry>
        <box size="0.0402 0.046 0.0651"/>
      </geometry>
      <origin rpy="0 1.57 1.57" xyz="0 0 0"/>
      <material name="silver">
        <color rgba="0.3 0.3 0.3 1"/>
      </material>
    </visual>
    <collision>
      <geometry>
        <box size="0.0402 0.046 0.0651"/>
      </geometry>
      <origin rpy="0 1.57 1.57" xyz="0 0 0"/>
    </collision>
    <inertial>
      <mass value="0.153"/>
      <inertia ixx="0.0" ixy="0.0" ixz="0.0" iyy="0.0" iyz="0.0" izz="0.0"/>
    </inertial>
  </link>
  <link name="link_lengan_kiri">
    <visual>
      <geometry>
        <cylinder length="0.15" radius="0.01"/>
      </geometry>
      <origin rpy="0.0 -1.57 0" xyz="0.08 0 0.0"/>
      <material name="white">
        <color rgba="0.8 0.8 0.8 1"/>
      </material>
    </visual>
    <collision>
      <geometry>
        <cylinder length="0.15" radius="0.01"/>
      </geometry>
      <origin rpy="0.0 -1.57 0" xyz="0.08 0 0.0"/>
    </collision>
    <inertial>
      <mass value="0.0015"/>
      <inertia ixx="0.0" ixy="0.0" ixz="0.0" iyy="0.0" iyz="0.0" izz="0.0"/>
    </inertial>
  </link>
  <link name="link_telapak_kiri">
    <visual>
      <geometry>
        <box size="0.015 0.07 0.04"/>
      </geometry>
      <origin rpy="0.0 0 0" xyz="0 0 0.0"/>
      <material name="black">
        <color rgba="0 0 0 1"/>
      </material>
    </visual>
    <collision>
      <geometry>
        <box size="0.015 0.07 0.04"/>
      </geometry>
      <origin rpy="0.0 0 0" xyz="0 0 0.0"/>
    </collision>
    <inertial>
      <mass value="4.2e-05"/>
      <inertia ixx="0.0" ixy="0.0" ixz="0.0" iyy="0.0" iyz="0.0" izz="0.0"/>
    </inertial>
  </link>
  <link name="telapak_tangan_kiri">
    <visual>
      <geometry>
        <cylinder length="0.01" radius="0.0625"/>
      </geometry>
      <origin rpy="0.0 0 0" xyz="0 0 0.0"/>
      <material name="black">
        <color rgba="0 0 0 1"/>
      </material>
    </visual>
    <collision>
      <geometry>
        <cylinder length="0.01" radius="0.0625"/>
      </geometry>
      <origin rpy="0.0 0 0" xyz="0 0 0.0"/>
    </collision>
    <inertial>
      <mass value="0.000625"/>
      <inertia ixx="0.0" ixy="0.0" ixz="0.0" iyy="0.0" iyz="0.0" izz="0.0"/>
    </inertial>
  </link>
  <!-- Tangan_Kiri_END -->
  <!-- Kepala -->
  <joint name="perut_to_kepala" type="fixed">
    <parent link="servo_perut_yaw"/>
    <child link="servo_kepala_yaw"/>
    <!--servo_kepala_roll-->
    <origin rpy="0 0 0" xyz="0 0.0 0.12"/>
    <limit effort="300" lower="-1.57" upper="1.57" velocity="0.1"/>
    <dynamics damping="50" friction="1"/>
    <axis xyz="0 0 1"/>
  </joint>
  <joint name="kepala_yaw" type="revolute">
    <parent link="servo_kepala_yaw"/>
    <child link="link_leher"/>
    <!--servo_kepala_roll-->
    <origin rpy="0 0 0" xyz="0 0.0 0.02"/>
    <limit effort="300" lower="-3.14" upper="3.14" velocity="0.1"/>
    <dynamics damping="50" friction="1"/>
    <axis xyz="0 0 1"/>
  </joint>
  <joint name="kepala_pitch" type="revolute">
    <parent link="link_leher"/>
    <child link="servo_kepala_pitch"/>
    <!--servo_kepala_roll-->
    <origin rpy="0 0 0" xyz="0 0.0 0.045"/>
    <limit effort="300" lower="-1.57" upper="1.57" velocity="0.1"/>
    <dynamics damping="50" friction="1"/>
    <axis xyz="0 1 0"/>
  </joint>
  <joint name="joint_kepala_yaw" type="fixed">
    <parent link="servo_kepala_pitch"/>
    <child link="servo_kepala_roll"/>
    <!--servo_kepala_roll-->
    <origin rpy="0 0 0" xyz="0 0.005 0.0"/>
    <limit effort="300" lower="-3.14" upper="3.14" velocity="0.1"/>
    <dynamics damping="50" friction="1"/>
    <axis xyz="0 0 1"/>
  </joint>
  <joint name="kepala_roll" type="revolute">
    <parent link="servo_kepala_roll"/>
    <child link="kepala"/>
    <!--servo_kepala_roll-->
    <origin rpy="0 0 0" xyz="0 0.0 0.0"/>
    <limit effort="300" lower="-1.57" upper="1.57" velocity="0.1"/>
    <dynamics damping="50" friction="1"/>
    <axis xyz="1 0 0"/>
  </joint>
  <!-- Kepala_END -->
  <!-- PERUT -->
  <joint name="joint_perut_roll" type="fixed">
    <parent link="base_link"/>
    <child link="servo_perut_roll_1"/>
    <origin rpy="0 0 0" xyz="0.055 0.0 0.1"/>
    <limit effort="300" lower="-1.57" upper="1.57" velocity="0.1"/>
    <dynamics damping="50" friction="1"/>
    <axis xyz="1 0 0"/>
  </joint>
  <joint name="joint_perut_roll_2" type="fixed">
    <parent link="base_link"/>
    <child link="servo_perut_roll_2"/>
    <origin rpy="0 0 0" xyz="-0.055 0.0 0.1"/>
    <limit effort="300" lower="-1.57" upper="1.57" velocity="0.1"/>
    <dynamics damping="50" friction="1"/>
    <axis xyz="1 0 0"/>
  </joint>
  <joint name="perut_roll" type="revolute">
    <parent link="servo_perut_roll_1"/>
    <child link="servo_perut_pitch"/>
    <origin rpy="0 0 0" xyz="-0.055 0.0 0.05"/>
    <limit effort="300" lower="-1.57" upper="1.57" velocity="0.1"/>
    <dynamics damping="50" friction="1"/>
    <axis xyz="1 0 0"/>
  </joint>
  <joint name="perut_pitch" type="revolute">
    <parent link="servo_perut_pitch"/>
    <child link="link_perut_yaw"/>
    <origin rpy="0 0 0" xyz="0 0.0 0.0"/>
    <limit effort="300" lower="-1.57" upper="1.57" velocity="0.1"/>
    <dynamics damping="50" friction="1"/>
    <axis xyz="0 1 0"/>
  </joint>
  <joint name="perut_yaw" type="revolute">
    <parent link="link_perut_yaw"/>
    <child link="servo_perut_yaw"/>
    <origin rpy="0 0 0" xyz="0.0 0.0 0.05"/>
    <limit effort="300" lower="-1.57" upper="1.57" velocity="0.1"/>
    <dynamics damping="50" friction="1"/>
    <axis xyz="0 0 1"/>
  </joint>
  <!-- PERUT_END -->
  <!-- Tangan -->
  <joint name="joint_bahu_kiri_yaw" type="fixed">
    <parent link="servo_kepala_yaw"/>
    <child link="servo_bahu_kiri_roll"/>
    <origin rpy="0 0 0" xyz="-0.08 0.0 0.0"/>
    <limit effort="300" lower="-1.57" upper="1.57" velocity="0.1"/>
    <dynamics damping="50" friction="1"/>
    <axis xyz="0 0 1"/>
  </joint>
  <joint name="bahu_kiri_roll" type="revolute">
    <parent link="servo_bahu_kiri_roll"/>
    <child link="servo_bahu_kiri_pitch"/>
    <origin rpy="0 0 0" xyz="-0.065 0.0 0.0015"/>
    <limit effort="300" lower="-3.14" upper="3.14" velocity="0.1"/>
    <dynamics damping="50" friction="1"/>
    <axis xyz="1 0 0"/>
  </joint>
  <joint name="joint_bahu_kanan_roll" type="fixed">
    <parent link="servo_kepala_yaw"/>
    <child link="servo_bahu_kanan_roll"/>
    <origin rpy="0 0 0" xyz="0.08 0.0 0.0"/>
    <limit effort="300" lower="-1.57" upper="1.57" velocity="0.1"/>
    <dynamics damping="50" friction="1"/>
    <axis xyz="0 0 1"/>
  </joint>
  <joint name="bahu_kanan_roll" type="revolute">
    <parent link="servo_bahu_kanan_roll"/>
    <child link="servo_bahu_kanan_pitch"/>
    <origin rpy="0 0 0" xyz="0.065 0.0 0.0015"/>
    <limit effort="300" lower="-3.14" upper="3.14" velocity="0.1"/>
    <dynamics damping="50" friction="1"/>
    <axis xyz="1 0 0"/>
  </joint>
  <joint name="bahu_kiri_yaw" type="revolute">
    <parent link="servo_bahu_kiri_pitch"/>
    <child link="link_siku_kiri"/>
    <origin rpy="0 0 0" xyz="-0.03 0.0 0.00"/>
    <limit effort="300" lower="-2.00" upper="2.00" velocity="0.1"/>
    <dynamics damping="50" friction="1"/>
    <axis xyz="0 1 0"/>
  </joint>
  <joint name="bahu_kanan_yaw" type="revolute">
    <parent link="servo_bahu_kanan_pitch"/>
    <child link="link_siku_kanan"/>
    <origin rpy="0 0 0" xyz="0.03 0.0 0.00"/>
    <limit effort="300" lower="-2.00" upper="2.00" velocity="0.1"/>
    <dynamics damping="50" friction="1"/>
    <axis xyz="0 1 0"/>
  </joint>
  <joint name="siku_kiri_yaw" type="revolute">
    <parent link="link_siku_kiri"/>
    <child link="servo_siku_kiri_pitch"/>
    <origin rpy="0 0 0" xyz="-0.195 0.0 0.00"/>
    <limit effort="300" lower="-2.00" upper="2.00" velocity="0.1"/>
    <dynamics damping="50" friction="1"/>
    <axis xyz="0 0 1"/>
  </joint>
  <joint name="siku_kanan_yaw" type="revolute">
    <parent link="link_siku_kanan"/>
    <child link="servo_siku_kanan_pitch"/>
    <origin rpy="0 0 0" xyz="0.195 0.0 0.00"/>
    <limit effort="300" lower="-2.00" upper="2.00" velocity="0.1"/>
    <dynamics damping="50" friction="1"/>
    <axis xyz="0 0 1"/>
  </joint>
  <joint name="joint_lengan_kiri_yaw" type="fixed">
    <parent link="servo_siku_kiri_pitch"/>
    <child link="link_lengan_kiri"/>
    <origin rpy="0 0 0" xyz="-0.16 0.0 0.00"/>
    <limit effort="300" lower="-1.57" upper="1.57" velocity="0.1"/>
    <dynamics damping="50" friction="1"/>
    <axis xyz="0 0 1"/>
  </joint>
  <joint name="joint_tangan_kiri" type="fixed">
    <parent link="link_lengan_kiri"/>
    <child link="link_telapak_kiri"/>
    <origin rpy="0 0 0" xyz="-0.0075 0.0 0.0"/>
    <limit effort="300" lower="-3.14" upper="3.14" velocity="0.1"/>
    <dynamics damping="50" friction="1"/>
  </joint>
  <joint name="tangan_kiri_EOF" type="fixed">
    <parent link="link_telapak_kiri"/>
    <child link="telapak_tangan_kiri"/>
    <origin rpy="0 0 0" xyz="-0.0625 0.0 0.02"/>
    <limit effort="300" lower="-3.14" upper="3.14" velocity="0.1"/>
    <dynamics damping="50" friction="1"/>
  </joint>
  <joint name="joint_lengan_kanan_yaw" type="fixed">
    <parent link="servo_siku_kanan_pitch"/>
    <child link="link_lengan_kanan"/>
    <origin rpy="0 0 0" xyz="0.16 0.0 0.00"/>
    <limit effort="300" lower="-1.57" upper="1.57" velocity="0.1"/>
    <dynamics damping="50" friction="1"/>
    <axis xyz="0 0 1"/>
  </joint>
  <joint name="joint_tangan_kanan" type="fixed">
    <parent link="link_lengan_kanan"/>
    <child link="link_telapak_kanan"/>
    <origin rpy="0 0 0" xyz="0.0075 0.0 0.0"/>
    <limit effort="300" lower="-3.14" upper="3.14" velocity="0.1"/>
    <dynamics damping="50" friction="1"/>
  </joint>
  <joint name="tangan_kanan_EOF" type="fixed">
    <parent link="link_telapak_kanan"/>
    <child link="telapak_tangan_kanan"/>
    <origin rpy="0 0 0" xyz="0.0625 0.0 0.02"/>
    <limit effort="300" lower="-3.14" upper="3.14" velocity="0.1"/>
    <dynamics damping="50" friction="1"/>
  </joint>
</robot>

